[2024-11-17T10:28:54.332+0000] {taskinstance.py:1159} INFO - Dependencies all met for dep_context=non-requeueable deps ti=<TaskInstance: etl_pipeline.load_task manual__2024-11-17T10:28:44.749546+00:00 [queued]>
[2024-11-17T10:28:54.339+0000] {taskinstance.py:1159} INFO - Dependencies all met for dep_context=requeueable deps ti=<TaskInstance: etl_pipeline.load_task manual__2024-11-17T10:28:44.749546+00:00 [queued]>
[2024-11-17T10:28:54.340+0000] {taskinstance.py:1361} INFO - Starting attempt 1 of 2
[2024-11-17T10:28:54.353+0000] {taskinstance.py:1382} INFO - Executing <Task(PythonOperator): load_task> on 2024-11-17 10:28:44.749546+00:00
[2024-11-17T10:28:54.359+0000] {standard_task_runner.py:57} INFO - Started process 3155 to run task
[2024-11-17T10:28:54.363+0000] {standard_task_runner.py:84} INFO - Running: ['***', 'tasks', 'run', 'etl_pipeline', 'load_task', 'manual__2024-11-17T10:28:44.749546+00:00', '--job-id', '15', '--raw', '--subdir', 'DAGS_FOLDER/etl_pipeline_dag.py', '--cfg-path', '/tmp/tmpiwxnxoui']
[2024-11-17T10:28:54.364+0000] {standard_task_runner.py:85} INFO - Job 15: Subtask load_task
[2024-11-17T10:28:54.410+0000] {task_command.py:416} INFO - Running <TaskInstance: etl_pipeline.load_task manual__2024-11-17T10:28:44.749546+00:00 [running]> on host af0ba0303f5b
[2024-11-17T10:28:54.486+0000] {taskinstance.py:1662} INFO - Exporting env vars: AIRFLOW_CTX_DAG_OWNER='***' AIRFLOW_CTX_DAG_ID='etl_pipeline' AIRFLOW_CTX_TASK_ID='load_task' AIRFLOW_CTX_EXECUTION_DATE='2024-11-17T10:28:44.749546+00:00' AIRFLOW_CTX_TRY_NUMBER='1' AIRFLOW_CTX_DAG_RUN_ID='manual__2024-11-17T10:28:44.749546+00:00'
[2024-11-17T10:28:54.504+0000] {etl_pipeline_dag.py:76} INFO - Starting to load data !!
[2024-11-17T10:28:54.509+0000] {load_data.py:13} INFO - Loading data into table Countries_by_GDP
[2024-11-17T10:28:54.551+0000] {taskinstance.py:1937} ERROR - Task failed with exception
Traceback (most recent call last):
  File "/home/airflow/.local/lib/python3.8/site-packages/airflow/operators/python.py", line 192, in execute
    return_value = self.execute_callable()
  File "/home/airflow/.local/lib/python3.8/site-packages/airflow/operators/python.py", line 209, in execute_callable
    return self.python_callable(*self.op_args, **self.op_kwargs)
  File "/opt/airflow/dags/etl_pipeline_dag.py", line 77, in load
    load_data(df, sql_connection, csv_path, table_name='Countries_by_GDP')
  File "/opt/airflow/dags/etl_scripts/load_data.py", line 15, in load_data
    load_to_csv(df,csv_path)
  File "/opt/airflow/dags/etl_scripts/load_data.py", line 10, in load_to_csv
    df.to_csv(csv_path)
  File "/home/airflow/.local/lib/python3.8/site-packages/pandas/core/generic.py", line 3772, in to_csv
    return DataFrameRenderer(formatter).to_csv(
  File "/home/airflow/.local/lib/python3.8/site-packages/pandas/io/formats/format.py", line 1186, in to_csv
    csv_formatter.save()
  File "/home/airflow/.local/lib/python3.8/site-packages/pandas/io/formats/csvs.py", line 240, in save
    with get_handle(
  File "/home/airflow/.local/lib/python3.8/site-packages/pandas/io/common.py", line 737, in get_handle
    check_parent_directory(str(handle))
  File "/home/airflow/.local/lib/python3.8/site-packages/pandas/io/common.py", line 600, in check_parent_directory
    raise OSError(rf"Cannot save file into a non-existent directory: '{parent}'")
OSError: Cannot save file into a non-existent directory: '../../output_files'
[2024-11-17T10:28:54.769+0000] {taskinstance.py:1400} INFO - Marking task as UP_FOR_RETRY. dag_id=etl_pipeline, task_id=load_task, execution_date=20241117T102844, start_date=20241117T102854, end_date=20241117T102854
[2024-11-17T10:28:54.806+0000] {standard_task_runner.py:104} ERROR - Failed to execute job 15 for task load_task (Cannot save file into a non-existent directory: '../../output_files'; 3155)
[2024-11-17T10:28:54.818+0000] {local_task_job_runner.py:228} INFO - Task exited with return code 1
[2024-11-17T10:28:54.832+0000] {taskinstance.py:2778} INFO - 0 downstream tasks scheduled from follow-on schedule check
