[2024-11-17T15:01:22.125+0000] {taskinstance.py:1159} INFO - Dependencies all met for dep_context=non-requeueable deps ti=<TaskInstance: etl_pipeline.extract_task scheduled__2024-11-17T14:01:18.955277+00:00 [queued]>
[2024-11-17T15:01:22.134+0000] {taskinstance.py:1159} INFO - Dependencies all met for dep_context=requeueable deps ti=<TaskInstance: etl_pipeline.extract_task scheduled__2024-11-17T14:01:18.955277+00:00 [queued]>
[2024-11-17T15:01:22.136+0000] {taskinstance.py:1361} INFO - Starting attempt 1 of 2
[2024-11-17T15:01:22.150+0000] {taskinstance.py:1382} INFO - Executing <Task(PythonOperator): extract_task> on 2024-11-17 14:01:18.955277+00:00
[2024-11-17T15:01:22.158+0000] {standard_task_runner.py:57} INFO - Started process 1347 to run task
[2024-11-17T15:01:22.162+0000] {standard_task_runner.py:84} INFO - Running: ['***', 'tasks', 'run', 'etl_pipeline', 'extract_task', 'scheduled__2024-11-17T14:01:18.955277+00:00', '--job-id', '27', '--raw', '--subdir', 'DAGS_FOLDER/etl_pipeline_dag.py', '--cfg-path', '/tmp/tmp8mr32eq9']
[2024-11-17T15:01:22.163+0000] {standard_task_runner.py:85} INFO - Job 27: Subtask extract_task
[2024-11-17T15:01:22.212+0000] {task_command.py:416} INFO - Running <TaskInstance: etl_pipeline.extract_task scheduled__2024-11-17T14:01:18.955277+00:00 [running]> on host af0ba0303f5b
[2024-11-17T15:01:22.301+0000] {taskinstance.py:1662} INFO - Exporting env vars: AIRFLOW_CTX_DAG_OWNER='***' AIRFLOW_CTX_DAG_ID='etl_pipeline' AIRFLOW_CTX_TASK_ID='extract_task' AIRFLOW_CTX_EXECUTION_DATE='2024-11-17T14:01:18.955277+00:00' AIRFLOW_CTX_TRY_NUMBER='1' AIRFLOW_CTX_DAG_RUN_ID='scheduled__2024-11-17T14:01:18.955277+00:00'
[2024-11-17T15:01:22.304+0000] {etl_pipeline_dag.py:41} INFO - Starting data extraction !!
[2024-11-17T15:26:10.958+0000] {taskinstance.py:1937} ERROR - Task failed with exception
Traceback (most recent call last):
  File "/home/airflow/.local/lib/python3.8/site-packages/urllib3/connectionpool.py", line 714, in urlopen
    httplib_response = self._make_request(
  File "/home/airflow/.local/lib/python3.8/site-packages/urllib3/connectionpool.py", line 466, in _make_request
    six.raise_from(e, None)
  File "<string>", line 3, in raise_from
  File "/home/airflow/.local/lib/python3.8/site-packages/urllib3/connectionpool.py", line 461, in _make_request
    httplib_response = conn.getresponse()
  File "/usr/local/lib/python3.8/http/client.py", line 1348, in getresponse
    response.begin()
  File "/usr/local/lib/python3.8/http/client.py", line 316, in begin
    version, status, reason = self._read_status()
  File "/usr/local/lib/python3.8/http/client.py", line 285, in _read_status
    raise RemoteDisconnected("Remote end closed connection without"
http.client.RemoteDisconnected: Remote end closed connection without response

During handling of the above exception, another exception occurred:

Traceback (most recent call last):
  File "/home/airflow/.local/lib/python3.8/site-packages/requests/adapters.py", line 486, in send
    resp = conn.urlopen(
  File "/home/airflow/.local/lib/python3.8/site-packages/urllib3/connectionpool.py", line 798, in urlopen
    retries = retries.increment(
  File "/home/airflow/.local/lib/python3.8/site-packages/urllib3/util/retry.py", line 550, in increment
    raise six.reraise(type(error), error, _stacktrace)
  File "/home/airflow/.local/lib/python3.8/site-packages/urllib3/packages/six.py", line 769, in reraise
    raise value.with_traceback(tb)
  File "/home/airflow/.local/lib/python3.8/site-packages/urllib3/connectionpool.py", line 714, in urlopen
    httplib_response = self._make_request(
  File "/home/airflow/.local/lib/python3.8/site-packages/urllib3/connectionpool.py", line 466, in _make_request
    six.raise_from(e, None)
  File "<string>", line 3, in raise_from
  File "/home/airflow/.local/lib/python3.8/site-packages/urllib3/connectionpool.py", line 461, in _make_request
    httplib_response = conn.getresponse()
  File "/usr/local/lib/python3.8/http/client.py", line 1348, in getresponse
    response.begin()
  File "/usr/local/lib/python3.8/http/client.py", line 316, in begin
    version, status, reason = self._read_status()
  File "/usr/local/lib/python3.8/http/client.py", line 285, in _read_status
    raise RemoteDisconnected("Remote end closed connection without"
urllib3.exceptions.ProtocolError: ('Connection aborted.', RemoteDisconnected('Remote end closed connection without response'))

During handling of the above exception, another exception occurred:

Traceback (most recent call last):
  File "/home/airflow/.local/lib/python3.8/site-packages/airflow/operators/python.py", line 192, in execute
    return_value = self.execute_callable()
  File "/home/airflow/.local/lib/python3.8/site-packages/airflow/operators/python.py", line 209, in execute_callable
    return self.python_callable(*self.op_args, **self.op_kwargs)
  File "/opt/airflow/dags/etl_pipeline_dag.py", line 42, in extract
    df = extract_data(url, table_attribs)
  File "/opt/airflow/dags/etl_scripts/extract_data.py", line 9, in extract_data
    page = requests.get(url).text
  File "/home/airflow/.local/lib/python3.8/site-packages/requests/api.py", line 73, in get
    return request("get", url, params=params, **kwargs)
  File "/home/airflow/.local/lib/python3.8/site-packages/requests/api.py", line 59, in request
    return session.request(method=method, url=url, **kwargs)
  File "/home/airflow/.local/lib/python3.8/site-packages/requests/sessions.py", line 589, in request
    resp = self.send(prep, **send_kwargs)
  File "/home/airflow/.local/lib/python3.8/site-packages/requests/sessions.py", line 703, in send
    r = adapter.send(request, **kwargs)
  File "/home/airflow/.local/lib/python3.8/site-packages/requests/adapters.py", line 501, in send
    raise ConnectionError(err, request=request)
requests.exceptions.ConnectionError: ('Connection aborted.', RemoteDisconnected('Remote end closed connection without response'))
[2024-11-17T15:26:11.289+0000] {taskinstance.py:1400} INFO - Marking task as UP_FOR_RETRY. dag_id=etl_pipeline, task_id=extract_task, execution_date=20241117T140118, start_date=20241117T150122, end_date=20241117T152611
[2024-11-17T15:26:11.308+0000] {standard_task_runner.py:104} ERROR - Failed to execute job 27 for task extract_task (('Connection aborted.', RemoteDisconnected('Remote end closed connection without response')); 1347)
[2024-11-17T15:26:11.326+0000] {local_task_job_runner.py:228} INFO - Task exited with return code 1
[2024-11-17T15:26:11.358+0000] {taskinstance.py:2778} INFO - 0 downstream tasks scheduled from follow-on schedule check
